Workbook

Sheet Raw Data
A1: Campaign_ID | B1: Campaign_Name | C1: Date | D1: Marketing_Channel | E1: Campaign_Type | F1: Region | G1: Impressions | H1: Clicks | I1: Leads | J1: Conversions | K1: Ad_Spend | L1: Revenue | M1: Customers | N1: Campaign_Duration | O1: Device_Type
A2: CMP_LI_01 | B2: LI_B2B_Executive_Leads | C2: 2025-02-06 | D2: linkedin ads | E2: Lead Generation | F2: Latin America | G2: 9893 | H2: 324 | I2: 89 | J2: 35 | K2: 1958.73 | L2: 19229.69 | M2: 16 | N2: 23 | O2: Tablet
A3: CMP_LI_01 | B3: LI_B2B_Executive_Leads | C3: 2025-07-22 | D3: linkedin ads | E3: Lead Generation | F3: Latin America | G3: 10538 | H3: 197 | I3: 85 | J3: 20 | K3: 2085.03 | L3: 14351.94 | M3: 10 | N3: 17 | O3: Desktop
A4: CMP_LI_01 | B4: LI_B2B_Executive_Leads | C4: 2025/08/05 | D4: LinkedIn Ads | E4: Lead Generation | F4: Europe | G4: 19266 | H4: 366 | I4: 171 | J4: 28 | K4: 3701.29 | L4: 17598.4 | M4: 13 | N4: 28 | O4: Desktop
A5: CMP_SEO_01 | B5: SEO_Organic_Blog_Content | C5: 2025-07-27 | D5: seo | E5: Awareness | F5: Asia-Pacific | G5: 36633 | H5: 2034 | I5: 810 | J5: 216 | K5: 506.92 | L5: 86354.24 | M5: 171 | N5: 20 | O5: Tablet
A6: CMP_GGL_01 | B6: Google_Search_Brand | C6: 2025-10-24 | D6: Google Ads | E6: Conversion | F6: Asia-Pacific | G6: 19738 | H6: 955 | I6: 506 | J6: 95 | K6: 3312.59 | L6: 30321.48 | M6: 65 | N6: 22 | O6: Tablet
A7: CMP_IG_01 | B7: IG_Influencer_Promos | C7: 2025-12-07 | D7: Instagram_Ads | E7: Product Promotion | F7: Latin America | G7: 44792 | H7: 2194 | I7: 782 | J7: 152 | K7: 4847.23 | L7: 36083.58 | M7: 97 | N7: 16 | O7: Mobile
A8: CMP_LI_02 | B8: LI_Whitepaper_Downloads | C8: 2025-05-13 | D8: linkedin ads | E8: Lead Generation | F8: Latin America | G8: 15702 | H8: 402 | I8: 208 | J8: 32 | K8: 3725.76 | L8: 22286.64 | M8: 20 | N8: 25 | O8: Desktop
A9: CMP_IG_02 | B9: IG_Stories_Conversion | C9: 2025-12-07 | D9: instagram ads | E9: Conversion | F9: Asia-Pacific | G9: 45324 | H9: 2373 | I9: 909 | J9: 129 | K9: 4542.94 | L9: 30947.5 | M9: 70 | N9: 12 | O9: Desktop
A10: CMP_IG_01 | B10: IG_Influencer_Promos | C10: 2025-07-21 | D10: instagram ads | E10: Product Promotion | F10: Middle East | G10: 28011 | H10: 1448 | I10: 394 | J10: 77 | K10: 3184.15 | L10: 15145.83 | M10: 41 | N10: 9 | O10: Tablet
A11: CMP_SEO_02 | B11: SEO_High_Intent_Landing | C11: 2025-11-07 | D11: seo | E11: Conversion | F11: North America | G11: 41943 | H11: 2556 | I11: 1213 | J11: 361 | K11: 676.14 | L11: 121137.68 | M11: 299 | N11: 25 | O11: Mobile
A12: CMP_IG_01 | B12: IG_Influencer_Promos | C12: 2025-12-22 | D12: instagram ads | E12: Product Promotion | F12: Asia-Pacific | G12: 23641 | H12: 1279 | I12: 540 | J12: 82 | K12: 4408.5 | L12: 18818.65 | M12: 49 | N12: 17 | O12: Tablet
A13: CMP_GGL_01 | B13: Google_Search_Brand | C13: 2025-11-04 | D13: GOOGLE ADS | E13: Conversion | F13: North America | G13: 12781 | H13: 752 | I13: 205 | J13: 91 | K13: 2941.02 | L13: 26128.84 | M13: 76 | N13: 10 | O13: Mobile
A14: CMP_SEO_02 | B14: SEO_High_Intent_Landing | C14: 2025-03-24 | D14: seo | E14: Conversion | F14: Latin America | G14: 19349 | H14: 1046 | I14: 270 | J14: 153 | K14: 461.13 | L14: 57439.8 | M14: 113 | N14: 23 | O14: Desktop
A15: CMP_FB_01 | B15: FB_Retargeting_Q1 | C15: 2025/05/03 | D15: facebook ads | E15: Retargeting | F15: Latin America | G15: 43474 | H15: 1212 | J15: 76 | K15: 3079.58 | L15: 18742.2 | M15: 51 | N15: 9
A16: CMP_EM_02 | B16: EM_Abandoned_Cart_Nurture | C16: 2025-01-16 | D16: Email Marketing | E16: Conversion | F16: Europe | G16: 28529 | H16: 3349 | I16: 1623 | J16: 604 | K16: 1282.62 | L16: 141171.84 | M16: 436 | N16: 19 | O16: Mobile
A17: CMP_FB_01 | B17: FB_Retargeting_Q1 | C17: 2025-01-25 | D17: Facebook Ads | E17: Retargeting | F17: Latin America | G17: 39214 | H17: 1148 | I17: 475 | J17: 90 | K17: 3033.45 | L17: 20732.22 | M17: 49 | N17: 12 | O17: Tablet
A18: CMP_SEO_01 | B18: SEO_Organic_Blog_Content | C18: 2025-05-20 | D18: seo | E18: Awareness | F18: North America | G18: 47152 | H18: 2316 | I18: 843 | J18: 269 | K18: 975.53 | L18: 75743.79 | M18: 206 | N18: 21 | O18: Tablet
A19: CMP_FB_02 | B19: FB_Lookalike_Prospecting | C19: 2025/12/05 | D19: Facebook Ads | E19: Awareness | F19: Europe | G19: 26391 | H19: 1023 | I19: 265 | J19: 82 | K19: 1806.73 | L19: 20412.84 | M19: 52 | N19: 14 | O19: Mobile
A20: CMP_LI_01 | B20: LI_B2B_Executive_Leads | C20: 2025-01-29 | D20: LinkedIn Ads | E20: Lead Generation | F20: Europe | G20: 9763 | H20: 313 | I20: 82 | J20: 37 | K20: 2921.85 | L20: 19962.7 | M20: 23 | N20: 8 | O20: Desktop
A21: CMP_YT_02 | B21: YT_TrueView_Product_Demo | C21: 2025-02-03 | D21: YouTube_Ads | E21: Product Promotion | F21: Middle East | G21: 63449 | H21: 1397 | I21: 356 | J21: 97 | K21: 2651.36 | L21: 18479.97 | M21: 60 | N21: 15 | O21: Desktop
A22: CMP_IG_02 | B22: IG_Stories_Conversion | C22: 2025-02-28 | D22: Instagram_Ads | E22: Conversion | F22: North America | G22: 35785 | H22: 1149 | I22: 342 | J22: 99 | K22: 3449.73 | L22: 25494.4 | M22: 61 | N22: 27 | O22: Desktop
A23: CMP_YT_02 | B23: YT_TrueView_Product_Demo | C23: 2025-04-13 | D23: YouTube Ads | E23: Product Promotion | F23: North America | G23: 78133 | H23: 1238 | I23: 326 | J23: 53 | K23: 1646.96 | L23: 9411.09 | M23: 27 | N23: 11 | O23: Desktop
A24: CMP_LI_02 | B24: LI_Whitepaper_Downloads | C24: 2025-03-14 | D24: linkedin ads | E24: Lead Generation | F24: North America | G24: 20475 | H24: 425 | I24: 186 | J24: 42 | K24: 4301.04 | L24: 26066.13 | M24: 22 | N24: 13 | O24: Mobile
A25: CMP_FB_01 | B25: FB_Retargeting_Q1 | C25: 2025-04-07 | D25: facebook ads | E25: Retargeting | F25: Europe | G25: 62534 | H25: 1591 | I25: 428 | J25: 159 | K25: 4858.27 | L25: 41233.63 | M25: 90 | N25: 15 | O25: Mobile
A26: CMP_FB_02 | B26: FB_Lookalike_Prospecting | C26: 2025-10-15 | D26: Facebook Ads | E26: Awareness | F26: Europe | G26: 37303 | H26: 1664 | I26: 842 | J26: 163 | K26: 4672.4 | L26: 38419.46 | M26: 118 | N26: 15 | O26: Desktop
A27: CMP_FB_02 | B27: FB_Lookalike_Prospecting | C27: 2025-06-02 | D27: facebook ads | E27: Awareness | F27: Latin America | G27: 58692 | H27: 1786 | J27: 163 | K27: 3021.87 | L27: 34629.57 | M27: 95 | N27: 8 | O27: Tablet
A28: CMP_SEO_01 | B28: SEO_Organic_Blog_Content | C28: 2025-08-12 | D28: SEO | E28: Awareness | F28: Latin America | G28: 55785 | H28: 2386 | I28: 878 | J28: 251 | K28: 1003.18 | L28: 64006.82 | M28: 199 | N28: 26 | O28: Mobile
A29: CMP_LI_02 | B29: LI_Whitepaper_Downloads | C29: 2025/11/10 | D29: LinkedIn Ads | E29: Lead Generation | F29: Latin America | G29: 15147 | H29: 420 | I29: 200 | J29: 33 | K29: 4369.05 | L29: 17980.46 | M29: 16 | N29: 13 | O29: Tablet
A30: CMP_DSP_01 | B30: DSP_Programmatic_Banner | C30: 2025-07-05 | D30: Display Ads | E30: Awareness | F30: Latin America | G30: 39734 | H30: 446 | I30: 198 | J30: 7 | K30: 1170.27 | L30: 957.07 | M30: 3 | N30: 17 | O30: Desktop
A31: CMP_SEO_02 | B31: SEO_High_Intent_Landing | C31: 2025/11/26 | D31: seo | E31: Conversion | F31: Europe | G31: 24196 | H31: 1921 | I31: 978 | J31: 230 | K31: 902.39 | L31: 60111.09 | M31: 188 | N31: 9 | O31: Tablet
A32: CMP_YT_02 | B32: YT_TrueView_Product_Demo | C32: 2025-12-11 | D32: YouTube Ads | E32: Product Promotion | F32: North America | G32: 39806 | H32: 865 | I32: 453 | J32: 33 | K32: 1578.72 | L32: 6129.25 | M32: 15 | N32: 30 | O32: Tablet
A33: CMP_EM_01 | B33: EM_Weekly_Newsletter | C33: 2025/09/24 | D33: Email Marketing | E33: Product Promotion | F33: Latin America | G33: 17446 | H33: 2076 | I33: 892 | J33: 317 | K33: 664.95 | L33: 70003.13 | M33: 239 | N33: 18 | O33: Desktop
A34: CMP_LI_02 | B34: LI_Whitepaper_Downloads | C34: 2025-09-05 | D34: linkedin ads | E34: Lead Generation | F34: Middle East | G34: 22472 | H34: 564 | I34: 270 | J34: 73 | K34: 4462.39 | L34: 48783.51 | M34: 46 | N34: 29 | O34: Mobile
A35: CMP_EM_02 | B35: EM_Abandoned_Cart_Nurture | C35: 2025-12-30 | D35: email marketing | E35: Conversion | F35: Middle East | G35: 15449 | H35: 1738 | I35: 778 | J35: 228 | K35: 1029.92 | L35: 51588.1 | M35: 169 | N35: 28 | O35: Tablet
A36: CMP_FB_01 | B36: FB_Retargeting_Q1 | C36: 2025/08/06 | D36: facebook ads | E36: Retargeting | F36: Latin America | G36: 26304 | H36: 909 | I36: 349 | J36: 58 | K36: 2821.86 | L36: 15278.81 | M36: 40 | N36: 15 | O36: Desktop
A37: CMP_IG_02 | B37: IG_Stories_Conversion | C37: 2025-01-07 | D37: Instagram Ads | E37: Conversion | F37: Latin America | G37: 16408 | H37: 741 | I37: 326 | J37: 46 | K37: 1821.34 | L37: 7551.83 | M37: 26 | N37: 8 | O37: Mobile
A38: CMP_YT_02 | B38: YT_TrueView_Product_Demo | C38: 2025-10-20 | D38: youtube ads | E38: Product Promotion | F38: Latin America | G38: 68546 | H38: 1167 | I38: 638 | J38: 51 | K38: 1942.62 | L38: 12441.17 | M38: 23 | N38: 13 | O38: Tablet
A39: CMP_SEO_02 | B39: SEO_High_Intent_Landing | C39: 2025-07-26 | D39: seo | E39: Conversion | F39: North America | G39: 42968 | H39: 2127 | I39: 755 | J39: 327 | K39: 1040.21 | L39: 84519.51 | M39: 275 | N39: 26 | O39: Tablet
... A107: CMP_DSP_02 | B107: DSP_Dynamic_Retargeting | C107: 2025-12-04 | D107: display ads | E107: Retargeting | F107: Asia-Pacific | G107: 39974 | H107: 493 | I107: 159 | J107: 11 | K107: 1246.79 | L107: 1586.91 | M107: 3 | N107: 25 | O107: Tablet
...

Sheet Cleaned Data
A1: Campaign_ID | B1: Campaign_Name | C1: Date | D1: Marketing_Channel | E1: Campaign_Type | F1: Region | G1: Impressions | H1: Clicks | I1: Leads | J1: Conversions | K1: Ad_Spend | L1: Revenue | M1: Customers | N1: Campaign_Duration | O1: Device_Type
A2: CMP_DSP_01 | B2: DSP_Programmatic_Banner | C2: 2025-01-01 | D2: Display Ads | E2: Awareness | F2: Asia-Pacific | G2: 44918 | H2: 792 | I2: 392 | J2: 27 | K2: 1930.4 | L2: 4806.64 | M2: 12 | N2: 17 | O2: Mobile
A3: CMP_EM_02 | B3: EM_Abandoned_Cart_Nurture | C3: 2025-01-01 | D3: Email Marketing | E3: Conversion | F3: North America | G3: 21991 | H3: 1882 | I3: 843 | J3: 410 | K3: 924.67 | L3: 112595.42 | M3: 290 | N3: 23 | O3: Tablet
A4: CMP_FB_02 | B4: FB_Lookalike_Prospecting | C4: 2025-01-01 | D4: Facebook Ads | E4: Awareness | F4: Asia-Pacific | G4: 64111 | H4: 1921 | I4: 1052 | J4: 163 | K4: 6055.17 | L4: 31887.43 | M4: 92 | N4: 12 | O4: Tablet
A5: CMP_GGL_01 | B5: Google_Search_Brand | C5: 2025-01-01 | D5: Google Ads | E5: Conversion | F5: Latin America | G5: 40970 | H5: 1568 | I5: 639 | J5: 178 | K5: 6488.15 | L5: 62078.16 | M5: 143 | N5: 14 | O5: Tablet
A6: CMP_GGL_01 | B6: Google_Search_Brand | C6: 2025-01-01 | D6: Google Ads | E6: Conversion | F6: Middle East | G6: 42185 | H6: 2503 | I6: 648 | J6: 298 | K6: 7323.06 | L6: 67348.93 | M6: 249 | N6: 17 | O6: Tablet
A7: CMP_GGL_01 | B7: Google_Search_Brand | C7: 2025-01-01 | D7: Google Ads | E7: Conversion | F7: Europe | G7: 39888 | H7: 2039 | I7: 607 | J7: 211 | K7: 7324.72 | L7: 60790.35 | M7: 151 | N7: 13 | O7: Desktop
A8: CMP_GGL_01 | B8: Google_Search_Brand | C8: 2025-01-01 | D8: Google Ads | E8: Conversion | F8: Latin America | G8: 38458 | H8: 2038 | I8: 1108 | J8: 210 | K8: 8793.31 | L8: 73457.51 | M8: 132 | N8: 23 | O8: Desktop
A9: CMP_LI_01 | B9: LI_B2B_Executive_Leads | C9: 2025-01-01 | D9: LinkedIn Ads | E9: Lead Generation | F9: North America | G9: 6365 | H9: 146 | I9: 79 | J9: 18 | K9: 1290.88 | L9: 8712.98 | M9: 10 | N9: 18 | O9: Mobile
A10: CMP_LI_02 | B10: LI_Whitepaper_Downloads | C10: 2025-01-01 | D10: LinkedIn Ads | E10: Lead Generation | F10: Middle East | G10: 6639 | H10: 213 | I10: 89 | J10: 26 | K10: 2286.33 | L10: 14066.88 | M10: 12 | N10: 26 | O10: Desktop
A11: CMP_SEO_02 | B11: SEO_High_Intent_Landing | C11: 2025-01-01 | D11: SEO | E11: Conversion | F11: Latin America | G11: 63042 | H11: 3993 | I11: 2058 | J11: 541 | K11: 1437.31 | L11: 207168.09 | M11: 393 | N11: 21 | O11: Tablet
A12: CMP_DSP_01 | B12: DSP_Programmatic_Banner | C12: 2025-01-02 | D12: Display Ads | E12: Awareness | F12: Middle East | G12: 77690 | H12: 459 | I12: 187 | J12: 9 | K12: 877.09 | L12: 1638.77 | M12: 3 | N12: 12 | O12: Mobile
A13: CMP_DSP_02 | B13: DSP_Dynamic_Retargeting | C13: 2025-01-02 | D13: Display Ads | E13: Retargeting | F13: North America | G13: 83723 | H13: 506 | I13: 169 | J13: 10 | K13: 941.03 | L13: 1726.4 | M13: 4 | N13: 24 | O13: Desktop
... A3001: CMP_YT_02 | B3001: YT_TrueView_Product_Demo | C3001: 2025-12-31 | D3001: YouTube Ads | E3001: Product Promotion | F3001: North America | G3001: 55120 | H3001: 1219 | I3001: 509 | J3001: 83 | K3001: 2621.34 | L3001: 14386.88 | M3001: 44 | N3001: 15 | O3001: Tablet

Sheet KPI Calculation
A1: Campaign_ID | B1: Campaign_Name | C1: Date | D1: Marketing_Channel | E1: Campaign_Type | F1: Region | G1: Impressions | H1: Clicks | I1: Leads | J1: Conversions | K1: Ad_Spend | L1: Revenue | M1: Customers | N1: Campaign_Duration | O1: Device_Type | P1: CTR (%) | Q1: Conversion Rate (%) | R1: CPC ($) | S1: CPL ($) | T1: CAC ($) | U1: ROAS (x) | V1: ROI (%)
A2: CMP_DSP_01 | B2: DSP_Programmatic_Banner | C2: 2025-01-01 | D2: Display Ads | E2: Awareness | F2: Asia-Pacific | G2: 44918 | H2: 792 | I2: 392 | J2: 27 | K2: 1930.4 | L2: 4806.64 | M2: 12 | N2: 17 | O2: Mobile | P2: =IFERROR(H2/G2*100, 0) -> 1.763213 | Q2: =IFERROR(J2/H2*100, 0) -> 3.4090909 | R2: =IFERROR(K2/H2, 0) -> 2.4373737 | S2: =IFERROR(K2/I2, 0) -> 4.9244898 | T2: =IFERROR(K2/M2, 0) -> 160.86667 | U2: =IFERROR(L2/K2, 0) -> 2.489971 | V2: =IFERROR((L2-K2)/K2*100, 0) -> 148.9971
A3: CMP_EM_02 | B3: EM_Abandoned_Cart_Nurture | C3: 2025-01-01 | D3: Email Marketing | E3: Conversion | F3: North America | G3: 21991 | H3: 1882 | I3: 843 | J3: 410 | K3: 924.67 | L3: 112595.42 | M3: 290 | N3: 23 | O3: Tablet | P3: =IFERROR(H3/G3*100, 0) -> 8.5580465 | Q3: =IFERROR(J3/H3*100, 0) -> 21.785335 | R3: =IFERROR(K3/H3, 0) -> 0.49132306 | S3: =IFERROR(K3/I3, 0) -> 1.0968802 | T3: =IFERROR(K3/M3, 0) -> 3.1885172 | U3: =IFERROR(L3/K3, 0) -> 121.76822 | V3: =IFERROR((L3-K3)/K3*100, 0) -> 12076.822
A4: CMP_FB_02 | B4: FB_Lookalike_Prospecting | C4: 2025-01-01 | D4: Facebook Ads | E4: Awareness | F4: Asia-Pacific | G4: 64111 | H4: 1921 | I4: 1052 | J4: 163 | K4: 6055.17 | L4: 31887.43 | M4: 92 | N4: 12 | O4: Tablet | P4: =IFERROR(H4/G4*100, 0) -> 2.9963657 | Q4: =IFERROR(J4/H4*100, 0) -> 8.485164 | R4: =IFERROR(K4/H4, 0) -> 3.1520927 | S4: =IFERROR(K4/I4, 0) -> 5.755865 | T4: =IFERROR(K4/M4, 0) -> 65.817065 | U4: =IFERROR(L4/K4, 0) -> 5.2661494 | V4: =IFERROR((L4-K4)/K4*100, 0) -> 426.61494
A5: CMP_GGL_01 | B5: Google_Search_Brand | C5: 2025-01-01 | D5: Google Ads | E5: Conversion | F5: Latin America | G5: 40970 | H5: 1568 | I5: 639 | J5: 178 | K5: 6488.15 | L5: 62078.16 | M5: 143 | N5: 14 | O5: Tablet | P5: =IFERROR(H5/G5*100, 0) -> 3.8271906 | Q5: =IFERROR(J5/H5*100, 0) -> 11.352041 | R5: =IFERROR(K5/H5, 0) -> 4.1378508 | S5: =IFERROR(K5/I5, 0) -> 10.153599 | T5: =IFERROR(K5/M5, 0) -> 45.371678 | U5: =IFERROR(L5/K5, 0) -> 9.5679292 | V5: =IFERROR((L5-K5)/K5*100, 0) -> 856.79292
A6: CMP_GGL_01 | B6: Google_Search_Brand | C6: 2025-01-01 | D6: Google Ads | E6: Conversion | F6: Middle East | G6: 42185 | H6: 2503 | I6: 648 | J6: 298 | K6: 7323.06 | L6: 67348.93 | M6: 249 | N6: 17 | O6: Tablet | P6: =IFERROR(H6/G6*100, 0) -> 5.9333886 | Q6: =IFERROR(J6/H6*100, 0) -> 11.905713 | R6: =IFERROR(K6/H6, 0) -> 2.9257131 | S6: =IFERROR(K6/I6, 0) -> 11.301019 | T6: =IFERROR(K6/M6, 0) -> 29.40988 | U6: =IFERROR(L6/K6, 0) -> 9.1968289 | V6: =IFERROR((L6-K6)/K6*100, 0) -> 819.68289
A7: CMP_GGL_01 | B7: Google_Search_Brand | C7: 2025-01-01 | D7: Google Ads | E7: Conversion | F7: Europe | G7: 39888 | H7: 2039 | I7: 607 | J7: 211 | K7: 7324.72 | L7: 60790.35 | M7: 151 | N7: 13 | O7: Desktop | P7: =IFERROR(H7/G7*100, 0) -> 5.1118131 | Q7: =IFERROR(J7/H7*100, 0) -> 10.34821 | R7: =IFERROR(K7/H7, 0) -> 3.59231 | S7: =IFERROR(K7/I7, 0) -> 12.067084 | T7: =IFERROR(K7/M7, 0) -> 48.508079 | U7: =IFERROR(L7/K7, 0) -> 8.2993411 | V7: =IFERROR((L7-K7)/K7*100, 0) -> 729.93411
A8: CMP_GGL_01 | B8: Google_Search_Brand | C8: 2025-01-01 | D8: Google Ads | E8: Conversion | F8: Latin America | G8: 38458 | H8: 2038 | I8: 1108 | J8: 210 | K8: 8793.31 | L8: 73457.51 | M8: 132 | N8: 23 | O8: Desktop | P8: =IFERROR(H8/G8*100, 0) -> 5.2992875 | Q8: =IFERROR(J8/H8*100, 0) -> 10.30422 | R8: =IFERROR(K8/H8, 0) -> 4.3146762 | S8: =IFERROR(K8/I8, 0) -> 7.9362004 | T8: =IFERROR(K8/M8, 0) -> 66.615985 | U8: =IFERROR(L8/K8, 0) -> 8.3537951 | V8: =IFERROR((L8-K8)/K8*100, 0) -> 735.37951
A9: CMP_LI_01 | B9: LI_B2B_Executive_Leads | C9: 2025-01-01 | D9: LinkedIn Ads | E9: Lead Generation | F9: North America | G9: 6365 | H9: 146 | I9: 79 | J9: 18 | K9: 1290.88 | L9: 8712.98 | M9: 10 | N9: 18 | O9: Mobile | P9: =IFERROR(H9/G9*100, 0) -> 2.2937942 | Q9: =IFERROR(J9/H9*100, 0) -> 12.328767 | R9: =IFERROR(K9/H9, 0) -> 8.8416438 | S9: =IFERROR(K9/I9, 0) -> 16.340253 | T9: =IFERROR(K9/M9, 0) -> 129.088 | U9: =IFERROR(L9/K9, 0) -> 6.7496437 | V9: =IFERROR((L9-K9)/K9*100, 0) -> 574.96437
A10: CMP_LI_02 | B10: LI_Whitepaper_Downloads | C10: 2025-01-01 | D10: LinkedIn Ads | E10: Lead Generation | F10: Middle East | G10: 6639 | H10: 213 | I10: 89 | J10: 26 | K10: 2286.33 | L10: 14066.88 | M10: 12 | N10: 26 | O10: Desktop | P10: =IFERROR(H10/G10*100, 0) -> 3.2083145 | Q10: =IFERROR(J10/H10*100, 0) -> 12.206573 | R10: =IFERROR(K10/H10, 0) -> 10.733944 | S10: =IFERROR(K10/I10, 0) -> 25.689101 | T10: =IFERROR(K10/M10, 0) -> 190.5275 | U10: =IFERROR(L10/K10, 0) -> 6.1526026 | V10: =IFERROR((L10-K10)/K10*100, 0) -> 515.26026
A11: CMP_SEO_02 | B11: SEO_High_Intent_Landing | C11: 2025-01-01 | D11: SEO | E11: Conversion | F11: Latin America | G11: 63042 | H11: 3993 | I11: 2058 | J11: 541 | K11: 1437.31 | L11: 207168.09 | M11: 393 | N11: 21 | O11: Tablet | P11: =IFERROR(H11/G11*100, 0) -> 6.3338727 | Q11: =IFERROR(J11/H11*100, 0) -> 13.54871 | R11: =IFERROR(K11/H11, 0) -> 0.35995743 | S11: =IFERROR(K11/I11, 0) -> 0.69840136 | T11: =IFERROR(K11/M11, 0) -> 3.6572774 | U11: =IFERROR(L11/K11, 0) -> 144.13598 | V11: =IFERROR((L11-K11)/K11*100, 0) -> 14313.598
A12: CMP_DSP_01 | B12: DSP_Programmatic_Banner | C12: 2025-01-02 | D12: Display Ads | E12: Awareness | F12: Middle East | G12: 77690 | H12: 459 | I12: 187 | J12: 9 | K12: 877.09 | L12: 1638.77 | M12: 3 | N12: 12 | O12: Mobile | P12: =IFERROR(H12/G12*100, 0) -> 0.59080963 | Q12: =IFERROR(J12/H12*100, 0) -> 1.9607843 | R12: =IFERROR(K12/H12, 0) -> 1.9108715 | S12: =IFERROR(K12/I12, 0) -> 4.6903209 | T12: =IFERROR(K12/M12, 0) -> 292.36333 | U12: =IFERROR(L12/K12, 0) -> 1.8684172 | V12: =IFERROR((L12-K12)/K12*100, 0) -> 86.841715
A13: CMP_DSP_02 | B13: DSP_Dynamic_Retargeting | C13: 2025-01-02 | D13: Display Ads | E13: Retargeting | F13: North America | G13: 83723 | H13: 506 | I13: 169 | J13: 10 | K13: 941.03 | L13: 1726.4 | M13: 4 | N13: 24 | O13: Desktop | P13: =IFERROR(H13/G13*100, 0) -> 0.60437395 | Q13: =IFERROR(J13/H13*100, 0) -> 1.9762846 | R13: =IFERROR(K13/H13, 0) -> 1.8597431 | S13: =IFERROR(K13/I13, 0) -> 5.5682249 | T13: =IFERROR(K13/M13, 0) -> 235.2575 | U13: =IFERROR(L13/K13, 0) -> 1.8345855 | V13: =IFERROR((L13-K13)/K13*100, 0) -> 83.458551
... A3001: CMP_YT_02 | B3001: YT_TrueView_Product_Demo | C3001: 2025-12-31 | D3001: YouTube Ads | E3001: Product Promotion | F3001: North America | G3001: 55120 | H3001: 1219 | I3001: 509 | J3001: 83 | K3001: 2621.34 | L3001: 14386.88 | M3001: 44 | N3001: 15 | O3001: Tablet | P3001: =IFERROR(H3001/G3001*100, 0) -> 2.2115385 | Q3001: =IFERROR(J3001/H3001*100, 0) -> 6.8088597 | R3001: =IFERROR(K3001/H3001, 0) -> 2.150402 | S3001: =IFERROR(K3001/I3001, 0) -> 5.1499804 | T3001: =IFERROR(K3001/M3001, 0) -> 59.575909 | U3001: =IFERROR(L3001/K3001, 0) -> 5.4883685 | V3001: =IFERROR((L3001-K3001)/K3001*100, 0) -> 448.83685

Sheet Channel Analysis
A1: Marketing Channel | B1: Total Impressions | C1: Total Clicks | D1: Total Leads | E1: Total Conversions | F1: Total Customers | G1: Total Ad Spend | H1: Total Revenue | I1: CTR (%) | J1: Conversion Rate (%) | K1: CPC ($) | L1: CPL ($) | M1: CAC ($) | N1: ROAS (x) | O1: ROI (%)
A2: Display Ads | B2: =SUMIF('Cleaned Data'!$D:$D, A2, 'Cleaned Data'!$G:$G) -> 21916763 | C2: =SUMIF('Cleaned Data'!$D:$D, A2, 'Cleaned Data'!$H:$H) -> 256247 | D2: =SUMIF('Cleaned Data'!$D:$D, A2, 'Cleaned Data'!$I:$I) -> 101046 | E2: =SUMIF('Cleaned Data'!$D:$D, A2, 'Cleaned Data'!$J:$J) -> 6664 | F2: =SUMIF('Cleaned Data'!$D:$D, A2, 'Cleaned Data'!$M:$M) -> 2807 | G2: =SUMIF('Cleaned Data'!$D:$D, A2, 'Cleaned Data'!$K:$K) -> 725860.59 | H2: =SUMIF('Cleaned Data'!$D:$D, A2, 'Cleaned Data'!$L:$L) -> 1006870.6 | I2: =IFERROR(C2/B2*100, 0) -> 1.1691827 | J2: =IFERROR(E2/C2*100, 0) -> 2.6006158 | K2: =IFERROR(G2/C2, 0) -> 2.8326599 | L2: =IFERROR(G2/D2, 0) -> 7.1834668 | M2: =IFERROR(G2/F2, 0) -> 258.58945 | N2: =IFERROR(H2/G2, 0) -> 1.3871405 | O2: =IFERROR((H2-G2)/G2*100, 0) -> 38.71405
A3: Email Marketing | B3: =SUMIF('Cleaned Data'!$D:$D, A3, 'Cleaned Data'!$G:$G) -> 6898141 | C3: =SUMIF('Cleaned Data'!$D:$D, A3, 'Cleaned Data'!$H:$H) -> 792218 | D3: =SUMIF('Cleaned Data'!$D:$D, A3, 'Cleaned Data'!$I:$I) -> 314752 | E3: =SUMIF('Cleaned Data'!$D:$D, A3, 'Cleaned Data'!$J:$J) -> 134004 | F3: =SUMIF('Cleaned Data'!$D:$D, A3, 'Cleaned Data'!$M:$M) -> 106928 | G3: =SUMIF('Cleaned Data'!$D:$D, A3, 'Cleaned Data'!$K:$K) -> 430646.34 | H3: =SUMIF('Cleaned Data'!$D:$D, A3, 'Cleaned Data'!$L:$L) -> 38674036 | I3: =IFERROR(C3/B3*100, 0) -> 11.484514 | J3: =IFERROR(E3/C3*100, 0) -> 16.915041 | K3: =IFERROR(G3/C3, 0) -> 0.54359575 | L3: =IFERROR(G3/D3, 0) -> 1.3682084 | M3: =IFERROR(G3/F3, 0) -> 4.0274422 | N3: =IFERROR(H3/G3, 0) -> 89.804632 | O3: =IFERROR((H3-G3)/G3*100, 0) -> 8880.4632
A4: Facebook Ads | B4: =SUMIF('Cleaned Data'!$D:$D, A4, 'Cleaned Data'!$G:$G) -> 15068396 | C4: =SUMIF('Cleaned Data'!$D:$D, A4, 'Cleaned Data'!$H:$H) -> 558329 | D4: =SUMIF('Cleaned Data'!$D:$D, A4, 'Cleaned Data'!$I:$I) -> 221966 | E4: =SUMIF('Cleaned Data'!$D:$D, A4, 'Cleaned Data'!$J:$J) -> 47270 | F4: =SUMIF('Cleaned Data'!$D:$D, A4, 'Cleaned Data'!$M:$M) -> 30248 | G4: =SUMIF('Cleaned Data'!$D:$D, A4, 'Cleaned Data'!$K:$K) -> 1310472.4 | H4: =SUMIF('Cleaned Data'!$D:$D, A4, 'Cleaned Data'!$L:$L) -> 10833223 | I4: =IFERROR(C4/B4*100, 0) -> 3.7052982 | J4: =IFERROR(E4/C4*100, 0) -> 8.4663344 | K4: =IFERROR(G4/C4, 0) -> 2.347133 | L4: =IFERROR(G4/D4, 0) -> 5.9039331 | M4: =IFERROR(G4/F4, 0) -> 43.324267 | N4: =IFERROR(H4/G4, 0) -> 8.2666545 | O4: =IFERROR((H4-G4)/G4*100, 0) -> 726.66545
A5: Google Ads | B5: =SUMIF('Cleaned Data'!$D:$D, A5, 'Cleaned Data'!$G:$G) -> 11806659 | C5: =SUMIF('Cleaned Data'!$D:$D, A5, 'Cleaned Data'!$H:$H) -> 587509 | D5: =SUMIF('Cleaned Data'!$D:$D, A5, 'Cleaned Data'!$I:$I) -> 230014 | E5: =SUMIF('Cleaned Data'!$D:$D, A5, 'Cleaned Data'!$J:$J) -> 64120 | F5: =SUMIF('Cleaned Data'!$D:$D, A5, 'Cleaned Data'!$M:$M) -> 46422 | G5: =SUMIF('Cleaned Data'!$D:$D, A5, 'Cleaned Data'!$K:$K) -> 2056606.2 | H5: =SUMIF('Cleaned Data'!$D:$D, A5, 'Cleaned Data'!$L:$L) -> 18379019 | I5: =IFERROR(C5/B5*100, 0) -> 4.9760817 | J5: =IFERROR(E5/C5*100, 0) -> 10.913875 | K5: =IFERROR(G5/C5, 0) -> 3.5005527 | L5: =IFERROR(G5/D5, 0) -> 8.9412218 | M5: =IFERROR(G5/F5, 0) -> 44.302404 | N5: =IFERROR(H5/G5, 0) -> 8.9365768 | O5: =IFERROR((H5-G5)/G5*100, 0) -> 793.65768
A6: Instagram Ads | B6: =SUMIF('Cleaned Data'!$D:$D, A6, 'Cleaned Data'!$G:$G) -> 12383776 | C6: =SUMIF('Cleaned Data'!$D:$D, A6, 'Cleaned Data'!$H:$H) -> 522073 | D6: =SUMIF('Cleaned Data'!$D:$D, A6, 'Cleaned Data'!$I:$I) -> 209784 | E6: =SUMIF('Cleaned Data'!$D:$D, A6, 'Cleaned Data'!$J:$J) -> 38674 | F6: =SUMIF('Cleaned Data'!$D:$D, A6, 'Cleaned Data'!$M:$M) -> 22986 | G6: =SUMIF('Cleaned Data'!$D:$D, A6, 'Cleaned Data'!$K:$K) -> 1412825.5 | H6: =SUMIF('Cleaned Data'!$D:$D, A6, 'Cleaned Data'!$L:$L) -> 8068018.3 | I6: =IFERROR(C6/B6*100, 0) -> 4.215782 | J6: =IFERROR(E6/C6*100, 0) -> 7.4077763 | K6: =IFERROR(G6/C6, 0) -> 2.7061838 | L6: =IFERROR(G6/D6, 0) -> 6.7346675 | M6: =IFERROR(G6/F6, 0) -> 61.464608 | N6: =IFERROR(H6/G6, 0) -> 5.7105555 | O6: =IFERROR((H6-G6)/G6*100, 0) -> 471.05555
A7: LinkedIn Ads | B7: =SUMIF('Cleaned Data'!$D:$D, A7, 'Cleaned Data'!$G:$G) -> 5421687 | C7: =SUMIF('Cleaned Data'!$D:$D, A7, 'Cleaned Data'!$H:$H) -> 134454 | D7: =SUMIF('Cleaned Data'!$D:$D, A7, 'Cleaned Data'!$I:$I) -> 53496 | E7: =SUMIF('Cleaned Data'!$D:$D, A7, 'Cleaned Data'!$J:$J) -> 13424 | F7: =SUMIF('Cleaned Data'!$D:$D, A7, 'Cleaned Data'!$M:$M) -> 6924 | G7: =SUMIF('Cleaned Data'!$D:$D, A7, 'Cleaned Data'!$K:$K) -> 1153256.1 | H7: =SUMIF('Cleaned Data'!$D:$D, A7, 'Cleaned Data'!$L:$L) -> 8001631.2 | I7: =IFERROR(C7/B7*100, 0) -> 2.4799292 | J7: =IFERROR(E7/C7*100, 0) -> 9.9840838 | K7: =IFERROR(G7/C7, 0) -> 8.5773282 | L7: =IFERROR(G7/D7, 0) -> 21.5578 | M7: =IFERROR(G7/F7, 0) -> 166.55923 | N7: =IFERROR(H7/G7, 0) -> 6.9382952 | O7: =IFERROR((H7-G7)/G7*100, 0) -> 593.82952
A8: SEO | B8: =SUMIF('Cleaned Data'!$D:$D, A8, 'Cleaned Data'!$G:$G) -> 16599118 | C8: =SUMIF('Cleaned Data'!$D:$D, A8, 'Cleaned Data'!$H:$H) -> 984711 | D8: =SUMIF('Cleaned Data'!$D:$D, A8, 'Cleaned Data'!$I:$I) -> 403035 | E8: =SUMIF('Cleaned Data'!$D:$D, A8, 'Cleaned Data'!$J:$J) -> 122736 | F8: =SUMIF('Cleaned Data'!$D:$D, A8, 'Cleaned Data'!$M:$M) -> 92325 | G8: =SUMIF('Cleaned Data'!$D:$D, A8, 'Cleaned Data'!$K:$K) -> 392405.3 | H8: =SUMIF('Cleaned Data'!$D:$D, A8, 'Cleaned Data'!$L:$L) -> 41080560 | I8: =IFERROR(C8/B8*100, 0) -> 5.9323092 | J8: =IFERROR(E8/C8*100, 0) -> 12.464165 | K8: =IFERROR(G8/C8, 0) -> 0.39849793 | L8: =IFERROR(G8/D8, 0) -> 0.97362586 | M8: =IFERROR(G8/F8, 0) -> 4.2502605 | N8: =IFERROR(H8/G8, 0) -> 104.68911 | O8: =IFERROR((H8-G8)/G8*100, 0) -> 10368.911
A9: YouTube Ads | B9: =SUMIF('Cleaned Data'!$D:$D, A9, 'Cleaned Data'!$G:$G) -> 22320611 | C9: =SUMIF('Cleaned Data'!$D:$D, A9, 'Cleaned Data'!$H:$H) -> 395506 | D9: =SUMIF('Cleaned Data'!$D:$D, A9, 'Cleaned Data'!$I:$I) -> 156809 | E9: =SUMIF('Cleaned Data'!$D:$D, A9, 'Cleaned Data'!$J:$J) -> 19446 | F9: =SUMIF('Cleaned Data'!$D:$D, A9, 'Cleaned Data'!$M:$M) -> 10620 | G9: =SUMIF('Cleaned Data'!$D:$D, A9, 'Cleaned Data'!$K:$K) -> 720636.32 | H9: =SUMIF('Cleaned Data'!$D:$D, A9, 'Cleaned Data'!$L:$L) -> 3895463.7 | I9: =IFERROR(C9/B9*100, 0) -> 1.7719318 | J9: =IFERROR(E9/C9*100, 0) -> 4.9167396 | K9: =IFERROR(G9/C9, 0) -> 1.8220617 | L9: =IFERROR(G9/D9, 0) -> 4.5956311 | M9: =IFERROR(G9/F9, 0) -> 67.856527 | N9: =IFERROR(H9/G9, 0) -> 5.405589 | O9: =IFERROR((H9-G9)/G9*100, 0) -> 440.5589

Sheet Campaign Analysis
A1: Campaign Name | B1: Channel | C1: Total Spend | D1: Total Revenue | E1: Total Conversions | F1: Total Customers | G1: Conversion Rate (%) | H1: CAC ($) | I1: ROAS (x) | J1: ROI (%)
A2: DSP_Dynamic_Retargeting | B2: Display Ads | C2: =SUMIF('Cleaned Data'!$B:$B, A2, 'Cleaned Data'!$K:$K) -> 376442.6 | D2: =SUMIF('Cleaned Data'!$B:$B, A2, 'Cleaned Data'!$L:$L) -> 526590.07 | E2: =SUMIF('Cleaned Data'!$B:$B, A2, 'Cleaned Data'!$J:$J) -> 3464 | F2: =SUMIF('Cleaned Data'!$B:$B, A2, 'Cleaned Data'!$M:$M) -> 1455 | G2: =IFERROR(E2/SUMIF('Cleaned Data'!$B:$B, A2, 'Cleaned Data'!$H:$H)*100, 0) -> 2.5978117 | H2: =IFERROR(C2/F2, 0) -> 258.72344 | I2: =IFERROR(D2/C2, 0) -> 1.3988589 | J2: =IFERROR((D2-C2)/C2*100, 0) -> 39.885887
A3: DSP_Programmatic_Banner | B3: Display Ads | C3: =SUMIF('Cleaned Data'!$B:$B, A3, 'Cleaned Data'!$K:$K) -> 349417.99 | D3: =SUMIF('Cleaned Data'!$B:$B, A3, 'Cleaned Data'!$L:$L) -> 480280.55 | E3: =SUMIF('Cleaned Data'!$B:$B, A3, 'Cleaned Data'!$J:$J) -> 3200 | F3: =SUMIF('Cleaned Data'!$B:$B, A3, 'Cleaned Data'!$M:$M) -> 1352 | G3: =IFERROR(E3/SUMIF('Cleaned Data'!$B:$B, A3, 'Cleaned Data'!$H:$H)*100, 0) -> 2.6036581 | H3: =IFERROR(C3/F3, 0) -> 258.44526 | I3: =IFERROR(D3/C3, 0) -> 1.3745158 | J3: =IFERROR((D3-C3)/C3*100, 0) -> 37.451581
A4: EM_Abandoned_Cart_Nurture | B4: Email Marketing | C4: =SUMIF('Cleaned Data'!$B:$B, A4, 'Cleaned Data'!$K:$K) -> 211092.73 | D4: =SUMIF('Cleaned Data'!$B:$B, A4, 'Cleaned Data'!$L:$L) -> 18232707 | E4: =SUMIF('Cleaned Data'!$B:$B, A4, 'Cleaned Data'!$J:$J) -> 64171 | F4: =SUMIF('Cleaned Data'!$B:$B, A4, 'Cleaned Data'!$M:$M) -> 51370 | G4: =IFERROR(E4/SUMIF('Cleaned Data'!$B:$B, A4, 'Cleaned Data'!$H:$H)*100, 0) -> 16.787177 | H4: =IFERROR(C4/F4, 0) -> 4.1092609 | I4: =IFERROR(D4/C4, 0) -> 86.372974 | J4: =IFERROR((D4-C4)/C4*100, 0) -> 8537.2974
A5: EM_Weekly_Newsletter | B5: Email Marketing | C5: =SUMIF('Cleaned Data'!$B:$B, A5, 'Cleaned Data'!$K:$K) -> 219553.61 | D5: =SUMIF('Cleaned Data'!$B:$B, A5, 'Cleaned Data'!$L:$L) -> 20441329 | E5: =SUMIF('Cleaned Data'!$B:$B, A5, 'Cleaned Data'!$J:$J) -> 69833 | F5: =SUMIF('Cleaned Data'!$B:$B, A5, 'Cleaned Data'!$M:$M) -> 55558 | G5: =IFERROR(E5/SUMIF('Cleaned Data'!$B:$B, A5, 'Cleaned Data'!$H:$H)*100, 0) -> 17.034267 | H5: =IFERROR(C5/F5, 0) -> 3.9517911 | I5: =IFERROR(D5/C5, 0) -> 93.104044 | J5: =IFERROR((D5-C5)/C5*100, 0) -> 9210.4044
A6: FB_Lookalike_Prospecting | B6: Facebook Ads | C6: =SUMIF('Cleaned Data'!$B:$B, A6, 'Cleaned Data'!$K:$K) -> 648451.16 | D6: =SUMIF('Cleaned Data'!$B:$B, A6, 'Cleaned Data'!$L:$L) -> 5433397.3 | E6: =SUMIF('Cleaned Data'!$B:$B, A6, 'Cleaned Data'!$J:$J) -> 23278 | F6: =SUMIF('Cleaned Data'!$B:$B, A6, 'Cleaned Data'!$M:$M) -> 14855 | G6: =IFERROR(E6/SUMIF('Cleaned Data'!$B:$B, A6, 'Cleaned Data'!$H:$H)*100, 0) -> 8.3892545 | H6: =IFERROR(C6/F6, 0) -> 43.652047 | I6: =IFERROR(D6/C6, 0) -> 8.3790387 | J6: =IFERROR((D6-C6)/C6*100, 0) -> 737.90387
A7: FB_Retargeting_Q1 | B7: Facebook Ads | C7: =SUMIF('Cleaned Data'!$B:$B, A7, 'Cleaned Data'!$K:$K) -> 662021.26 | D7: =SUMIF('Cleaned Data'!$B:$B, A7, 'Cleaned Data'!$L:$L) -> 5399825.4 | E7: =SUMIF('Cleaned Data'!$B:$B, A7, 'Cleaned Data'!$J:$J) -> 23992 | F7: =SUMIF('Cleaned Data'!$B:$B, A7, 'Cleaned Data'!$M:$M) -> 15393 | G7: =IFERROR(E7/SUMIF('Cleaned Data'!$B:$B, A7, 'Cleaned Data'!$H:$H)*100, 0) -> 8.5424863 | H7: =IFERROR(C7/F7, 0) -> 43.007943 | I7: =IFERROR(D7/C7, 0) -> 8.156574 | J7: =IFERROR((D7-C7)/C7*100, 0) -> 715.6574
A8: Google_NonBrand_Generic | B8: Google Ads | C8: =SUMIF('Cleaned Data'!$B:$B, A8, 'Cleaned Data'!$K:$K) -> 892744.42 | D8: =SUMIF('Cleaned Data'!$B:$B, A8, 'Cleaned Data'!$L:$L) -> 7814615.6 | E8: =SUMIF('Cleaned Data'!$B:$B, A8, 'Cleaned Data'!$J:$J) -> 27294 | F8: =SUMIF('Cleaned Data'!$B:$B, A8, 'Cleaned Data'!$M:$M) -> 19652 | G8: =IFERROR(E8/SUMIF('Cleaned Data'!$B:$B, A8, 'Cleaned Data'!$H:$H)*100, 0) -> 10.723168 | H8: =IFERROR(C8/F8, 0) -> 45.427662 | I8: =IFERROR(D8/C8, 0) -> 8.7534746 | J8: =IFERROR((D8-C8)/C8*100, 0) -> 775.34746
A9: Google_Search_Brand | B9: Google Ads | C9: =SUMIF('Cleaned Data'!$B:$B, A9, 'Cleaned Data'!$K:$K) -> 1163861.8 | D9: =SUMIF('Cleaned Data'!$B:$B, A9, 'Cleaned Data'!$L:$L) -> 10564404 | E9: =SUMIF('Cleaned Data'!$B:$B, A9, 'Cleaned Data'!$J:$J) -> 36826 | F9: =SUMIF('Cleaned Data'!$B:$B, A9, 'Cleaned Data'!$M:$M) -> 26770 | G9: =IFERROR(E9/SUMIF('Cleaned Data'!$B:$B, A9, 'Cleaned Data'!$H:$H)*100, 0) -> 11.059656 | H9: =IFERROR(C9/F9, 0) -> 43.476346 | I9: =IFERROR(D9/C9, 0) -> 9.077026 | J9: =IFERROR((D9-C9)/C9*100, 0) -> 807.7026
A10: IG_Influencer_Promos | B10: Instagram Ads | C10: =SUMIF('Cleaned Data'!$B:$B, A10, 'Cleaned Data'!$K:$K) -> 749425.15 | D10: =SUMIF('Cleaned Data'!$B:$B, A10, 'Cleaned Data'!$L:$L) -> 4148775.7 | E10: =SUMIF('Cleaned Data'!$B:$B, A10, 'Cleaned Data'!$J:$J) -> 20055 | F10: =SUMIF('Cleaned Data'!$B:$B, A10, 'Cleaned Data'!$M:$M) -> 11895 | G10: =IFERROR(E10/SUMIF('Cleaned Data'!$B:$B, A10, 'Cleaned Data'!$H:$H)*100, 0) -> 7.3318393 | H10: =IFERROR(C10/F10, 0) -> 63.003375 | I10: =IFERROR(D10/C10, 0) -> 5.535944 | J10: =IFERROR((D10-C10)/C10*100, 0) -> 453.5944
A11: IG_Stories_Conversion | B11: Instagram Ads | C11: =SUMIF('Cleaned Data'!$B:$B, A11, 'Cleaned Data'!$K:$K) -> 663400.34 | D11: =SUMIF('Cleaned Data'!$B:$B, A11, 'Cleaned Data'!$L:$L) -> 3919242.6 | E11: =SUMIF('Cleaned Data'!$B:$B, A11, 'Cleaned Data'!$J:$J) -> 18619 | F11: =SUMIF('Cleaned Data'!$B:$B, A11, 'Cleaned Data'!$M:$M) -> 11091 | G11: =IFERROR(E11/SUMIF('Cleaned Data'!$B:$B, A11, 'Cleaned Data'!$H:$H)*100, 0) -> 7.4913495 | H11: =IFERROR(C11/F11, 0) -> 59.814294 | I11: =IFERROR(D11/C11, 0) -> 5.9078092 | J11: =IFERROR((D11-C11)/C11*100, 0) -> 490.78092
A12: LI_B2B_Executive_Leads | B12: LinkedIn Ads | C12: =SUMIF('Cleaned Data'!$B:$B, A12, 'Cleaned Data'!$K:$K) -> 515405.02 | D12: =SUMIF('Cleaned Data'!$B:$B, A12, 'Cleaned Data'!$L:$L) -> 3581553.4 | E12: =SUMIF('Cleaned Data'!$B:$B, A12, 'Cleaned Data'!$J:$J) -> 5966 | F12: =SUMIF('Cleaned Data'!$B:$B, A12, 'Cleaned Data'!$M:$M) -> 3041 | G12: =IFERROR(E12/SUMIF('Cleaned Data'!$B:$B, A12, 'Cleaned Data'!$H:$H)*100, 0) -> 9.9715862 | H12: =IFERROR(C12/F12, 0) -> 169.48537 | I12: =IFERROR(D12/C12, 0) -> 6.9490076 | J12: =IFERROR((D12-C12)/C12*100, 0) -> 594.90076
A13: LI_Whitepaper_Downloads | B13: LinkedIn Ads | C13: =SUMIF('Cleaned Data'!$B:$B, A13, 'Cleaned Data'!$K:$K) -> 637851.07 | D13: =SUMIF('Cleaned Data'!$B:$B, A13, 'Cleaned Data'!$L:$L) -> 4420077.8 | E13: =SUMIF('Cleaned Data'!$B:$B, A13, 'Cleaned Data'!$J:$J) -> 7458 | F13: =SUMIF('Cleaned Data'!$B:$B, A13, 'Cleaned Data'!$M:$M) -> 3883 | G13: =IFERROR(E13/SUMIF('Cleaned Data'!$B:$B, A13, 'Cleaned Data'!$H:$H)*100, 0) -> 9.9941038 | H13: =IFERROR(C13/F13, 0) -> 164.26759 | I13: =IFERROR(D13/C13, 0) -> 6.9296392 | J13: =IFERROR((D13-C13)/C13*100, 0) -> 592.96392
... A17: YT_Video_Awareness_V1 | B17: YouTube Ads | C17: =SUMIF('Cleaned Data'!$B:$B, A17, 'Cleaned Data'!$K:$K) -> 360083.86 | D17: =SUMIF('Cleaned Data'!$B:$B, A17, 'Cleaned Data'!$L:$L) -> 1882568.5 | E17: =SUMIF('Cleaned Data'!$B:$B, A17, 'Cleaned Data'!$J:$J) -> 9506 | F17: =SUMIF('Cleaned Data'!$B:$B, A17, 'Cleaned Data'!$M:$M) -> 5232 | G17: =IFERROR(E17/SUMIF('Cleaned Data'!$B:$B, A17, 'Cleaned Data'!$H:$H)*100, 0) -> 4.8932906 | H17: =IFERROR(C17/F17, 0) -> 68.823368 | I17: =IFERROR(D17/C17, 0) -> 5.2281391 | J17: =IFERROR((D17-C17)/C17*100, 0) -> 422.81391

Sheet Monthly Analysis
A1: Year-Month | B1: Monthly Spend | C1: Monthly Revenue | D1: Conversions | E1: Customers | F1: Conversion Rate (%) | G1: CAC ($) | H1: ROAS (x) | I1: ROI (%)
A2: 2025-01 | B2: =SUMIFS('Cleaned Data'!$K:$K, 'Cleaned Data'!$C:$C, ">=2025-01-01", 'Cleaned Data'!$C:$C, "<=2025-01-31") -> 0 | C2: =SUMIFS('Cleaned Data'!$L:$L, 'Cleaned Data'!$C:$C, ">=2025-01-01", 'Cleaned Data'!$C:$C, "<=2025-01-31") -> 0 | D2: =SUMIFS('Cleaned Data'!$J:$J, 'Cleaned Data'!$C:$C, ">=2025-01-01", 'Cleaned Data'!$C:$C, "<=2025-01-31") -> 0 | E2: =SUMIFS('Cleaned Data'!$M:$M, 'Cleaned Data'!$C:$C, ">=2025-01-01", 'Cleaned Data'!$C:$C, "<=2025-01-31") -> 0 | F2: =IFERROR(D2/SUMIFS('Cleaned Data'!$H:$H, 'Cleaned Data'!$C:$C, ">=2025-01-01", 'Cleaned Data'!$C:$C, "<=2025-01-31")*100, 0) -> 0 | G2: =IFERROR(B2/E2, 0) -> 0 | H2: =IFERROR(C2/B2, 0) -> 0 | I2: =IFERROR((C2-B2)/B2*100, 0) -> 0
A3: 2025-02 | B3: =SUMIFS('Cleaned Data'!$K:$K, 'Cleaned Data'!$C:$C, ">=2025-02-01", 'Cleaned Data'!$C:$C, "<=2025-02-31") -> 0 | C3: =SUMIFS('Cleaned Data'!$L:$L, 'Cleaned Data'!$C:$C, ">=2025-02-01", 'Cleaned Data'!$C:$C, "<=2025-02-31") -> 0 | D3: =SUMIFS('Cleaned Data'!$J:$J, 'Cleaned Data'!$C:$C, ">=2025-02-01", 'Cleaned Data'!$C:$C, "<=2025-02-31") -> 0 | E3: =SUMIFS('Cleaned Data'!$M:$M, 'Cleaned Data'!$C:$C, ">=2025-02-01", 'Cleaned Data'!$C:$C, "<=2025-02-31") -> 0 | F3: =IFERROR(D3/SUMIFS('Cleaned Data'!$H:$H, 'Cleaned Data'!$C:$C, ">=2025-02-01", 'Cleaned Data'!$C:$C, "<=2025-02-31")*100, 0) -> 0 | G3: =IFERROR(B3/E3, 0) -> 0 | H3: =IFERROR(C3/B3, 0) -> 0 | I3: =IFERROR((C3-B3)/B3*100, 0) -> 0
A4: 2025-03 | B4: =SUMIFS('Cleaned Data'!$K:$K, 'Cleaned Data'!$C:$C, ">=2025-03-01", 'Cleaned Data'!$C:$C, "<=2025-03-31") -> 0 | C4: =SUMIFS('Cleaned Data'!$L:$L, 'Cleaned Data'!$C:$C, ">=2025-03-01", 'Cleaned Data'!$C:$C, "<=2025-03-31") -> 0 | D4: =SUMIFS('Cleaned Data'!$J:$J, 'Cleaned Data'!$C:$C, ">=2025-03-01", 'Cleaned Data'!$C:$C, "<=2025-03-31") -> 0 | E4: =SUMIFS('Cleaned Data'!$M:$M, 'Cleaned Data'!$C:$C, ">=2025-03-01", 'Cleaned Data'!$C:$C, "<=2025-03-31") -> 0 | F4: =IFERROR(D4/SUMIFS('Cleaned Data'!$H:$H, 'Cleaned Data'!$C:$C, ">=2025-03-01", 'Cleaned Data'!$C:$C, "<=2025-03-31")*100, 0) -> 0 | G4: =IFERROR(B4/E4, 0) -> 0 | H4: =IFERROR(C4/B4, 0) -> 0 | I4: =IFERROR((C4-B4)/B4*100, 0) -> 0
A5: 2025-04 | B5: =SUMIFS('Cleaned Data'!$K:$K, 'Cleaned Data'!$C:$C, ">=2025-04-01", 'Cleaned Data'!$C:$C, "<=2025-04-31") -> 0 | C5: =SUMIFS('Cleaned Data'!$L:$L, 'Cleaned Data'!$C:$C, ">=2025-04-01", 'Cleaned Data'!$C:$C, "<=2025-04-31") -> 0 | D5: =SUMIFS('Cleaned Data'!$J:$J, 'Cleaned Data'!$C:$C, ">=2025-04-01", 'Cleaned Data'!$C:$C, "<=2025-04-31") -> 0 | E5: =SUMIFS('Cleaned Data'!$M:$M, 'Cleaned Data'!$C:$C, ">=2025-04-01", 'Cleaned Data'!$C:$C, "<=2025-04-31") -> 0 | F5: =IFERROR(D5/SUMIFS('Cleaned Data'!$H:$H, 'Cleaned Data'!$C:$C, ">=2025-04-01", 'Cleaned Data'!$C:$C, "<=2025-04-31")*100, 0) -> 0 | G5: =IFERROR(B5/E5, 0) -> 0 | H5: =IFERROR(C5/B5, 0) -> 0 | I5: =IFERROR((C5-B5)/B5*100, 0) -> 0
A6: 2025-05 | B6: =SUMIFS('Cleaned Data'!$K:$K, 'Cleaned Data'!$C:$C, ">=2025-05-01", 'Cleaned Data'!$C:$C, "<=2025-05-31") -> 0 | C6: =SUMIFS('Cleaned Data'!$L:$L, 'Cleaned Data'!$C:$C, ">=2025-05-01", 'Cleaned Data'!$C:$C, "<=2025-05-31") -> 0 | D6: =SUMIFS('Cleaned Data'!$J:$J, 'Cleaned Data'!$C:$C, ">=2025-05-01", 'Cleaned Data'!$C:$C, "<=2025-05-31") -> 0 | E6: =SUMIFS('Cleaned Data'!$M:$M, 'Cleaned Data'!$C:$C, ">=2025-05-01", 'Cleaned Data'!$C:$C, "<=2025-05-31") -> 0 | F6: =IFERROR(D6/SUMIFS('Cleaned Data'!$H:$H, 'Cleaned Data'!$C:$C, ">=2025-05-01", 'Cleaned Data'!$C:$C, "<=2025-05-31")*100, 0) -> 0 | G6: =IFERROR(B6/E6, 0) -> 0 | H6: =IFERROR(C6/B6, 0) -> 0 | I6: =IFERROR((C6-B6)/B6*100, 0) -> 0
A7: 2025-06 | B7: =SUMIFS('Cleaned Data'!$K:$K, 'Cleaned Data'!$C:$C, ">=2025-06-01", 'Cleaned Data'!$C:$C, "<=2025-06-31") -> 0 | C7: =SUMIFS('Cleaned Data'!$L:$L, 'Cleaned Data'!$C:$C, ">=2025-06-01", 'Cleaned Data'!$C:$C, "<=2025-06-31") -> 0 | D7: =SUMIFS('Cleaned Data'!$J:$J, 'Cleaned Data'!$C:$C, ">=2025-06-01", 'Cleaned Data'!$C:$C, "<=2025-06-31") -> 0 | E7: =SUMIFS('Cleaned Data'!$M:$M, 'Cleaned Data'!$C:$C, ">=2025-06-01", 'Cleaned Data'!$C:$C, "<=2025-06-31") -> 0 | F7: =IFERROR(D7/SUMIFS('Cleaned Data'!$H:$H, 'Cleaned Data'!$C:$C, ">=2025-06-01", 'Cleaned Data'!$C:$C, "<=2025-06-31")*100, 0) -> 0 | G7: =IFERROR(B7/E7, 0) -> 0 | H7: =IFERROR(C7/B7, 0) -> 0 | I7: =IFERROR((C7-B7)/B7*100, 0) -> 0
A8: 2025-07 | B8: =SUMIFS('Cleaned Data'!$K:$K, 'Cleaned Data'!$C:$C, ">=2025-07-01", 'Cleaned Data'!$C:$C, "<=2025-07-31") -> 0 | C8: =SUMIFS('Cleaned Data'!$L:$L, 'Cleaned Data'!$C:$C, ">=2025-07-01", 'Cleaned Data'!$C:$C, "<=2025-07-31") -> 0 | D8: =SUMIFS('Cleaned Data'!$J:$J, 'Cleaned Data'!$C:$C, ">=2025-07-01", 'Cleaned Data'!$C:$C, "<=2025-07-31") -> 0 | E8: =SUMIFS('Cleaned Data'!$M:$M, 'Cleaned Data'!$C:$C, ">=2025-07-01", 'Cleaned Data'!$C:$C, "<=2025-07-31") -> 0 | F8: =IFERROR(D8/SUMIFS('Cleaned Data'!$H:$H, 'Cleaned Data'!$C:$C, ">=2025-07-01", 'Cleaned Data'!$C:$C, "<=2025-07-31")*100, 0) -> 0 | G8: =IFERROR(B8/E8, 0) -> 0 | H8: =IFERROR(C8/B8, 0) -> 0 | I8: =IFERROR((C8-B8)/B8*100, 0) -> 0
A9: 2025-08 | B9: =SUMIFS('Cleaned Data'!$K:$K, 'Cleaned Data'!$C:$C, ">=2025-08-01", 'Cleaned Data'!$C:$C, "<=2025-08-31") -> 0 | C9: =SUMIFS('Cleaned Data'!$L:$L, 'Cleaned Data'!$C:$C, ">=2025-08-01", 'Cleaned Data'!$C:$C, "<=2025-08-31") -> 0 | D9: =SUMIFS('Cleaned Data'!$J:$J, 'Cleaned Data'!$C:$C, ">=2025-08-01", 'Cleaned Data'!$C:$C, "<=2025-08-31") -> 0 | E9: =SUMIFS('Cleaned Data'!$M:$M, 'Cleaned Data'!$C:$C, ">=2025-08-01", 'Cleaned Data'!$C:$C, "<=2025-08-31") -> 0 | F9: =IFERROR(D9/SUMIFS('Cleaned Data'!$H:$H, 'Cleaned Data'!$C:$C, ">=2025-08-01", 'Cleaned Data'!$C:$C, "<=2025-08-31")*100, 0) -> 0 | G9: =IFERROR(B9/E9, 0) -> 0 | H9: =IFERROR(C9/B9, 0) -> 0 | I9: =IFERROR((C9-B9)/B9*100, 0) -> 0
A10: 2025-09 | B10: =SUMIFS('Cleaned Data'!$K:$K, 'Cleaned Data'!$C:$C, ">=2025-09-01", 'Cleaned Data'!$C:$C, "<=2025-09-31") -> 0 | C10: =SUMIFS('Cleaned Data'!$L:$L, 'Cleaned Data'!$C:$C, ">=2025-09-01", 'Cleaned Data'!$C:$C, "<=2025-09-31") -> 0 | D10: =SUMIFS('Cleaned Data'!$J:$J, 'Cleaned Data'!$C:$C, ">=2025-09-01", 'Cleaned Data'!$C:$C, "<=2025-09-31") -> 0 | E10: =SUMIFS('Cleaned Data'!$M:$M, 'Cleaned Data'!$C:$C, ">=2025-09-01", 'Cleaned Data'!$C:$C, "<=2025-09-31") -> 0 | F10: =IFERROR(D10/SUMIFS('Cleaned Data'!$H:$H, 'Cleaned Data'!$C:$C, ">=2025-09-01", 'Cleaned Data'!$C:$C, "<=2025-09-31")*100, 0) -> 0 | G10: =IFERROR(B10/E10, 0) -> 0 | H10: =IFERROR(C10/B10, 0) -> 0 | I10: =IFERROR((C10-B10)/B10*100, 0) -> 0
A11: 2025-10 | B11: =SUMIFS('Cleaned Data'!$K:$K, 'Cleaned Data'!$C:$C, ">=2025-10-01", 'Cleaned Data'!$C:$C, "<=2025-10-31") -> 0 | C11: =SUMIFS('Cleaned Data'!$L:$L, 'Cleaned Data'!$C:$C, ">=2025-10-01", 'Cleaned Data'!$C:$C, "<=2025-10-31") -> 0 | D11: =SUMIFS('Cleaned Data'!$J:$J, 'Cleaned Data'!$C:$C, ">=2025-10-01", 'Cleaned Data'!$C:$C, "<=2025-10-31") -> 0 | E11: =SUMIFS('Cleaned Data'!$M:$M, 'Cleaned Data'!$C:$C, ">=2025-10-01", 'Cleaned Data'!$C:$C, "<=2025-10-31") -> 0 | F11: =IFERROR(D11/SUMIFS('Cleaned Data'!$H:$H, 'Cleaned Data'!$C:$C, ">=2025-10-01", 'Cleaned Data'!$C:$C, "<=2025-10-31")*100, 0) -> 0 | G11: =IFERROR(B11/E11, 0) -> 0 | H11: =IFERROR(C11/B11, 0) -> 0 | I11: =IFERROR((C11-B11)/B11*100, 0) -> 0
A12: 2025-11 | B12: =SUMIFS('Cleaned Data'!$K:$K, 'Cleaned Data'!$C:$C, ">=2025-11-01", 'Cleaned Data'!$C:$C, "<=2025-11-31") -> 0 | C12: =SUMIFS('Cleaned Data'!$L:$L, 'Cleaned Data'!$C:$C, ">=2025-11-01", 'Cleaned Data'!$C:$C, "<=2025-11-31") -> 0 | D12: =SUMIFS('Cleaned Data'!$J:$J, 'Cleaned Data'!$C:$C, ">=2025-11-01", 'Cleaned Data'!$C:$C, "<=2025-11-31") -> 0 | E12: =SUMIFS('Cleaned Data'!$M:$M, 'Cleaned Data'!$C:$C, ">=2025-11-01", 'Cleaned Data'!$C:$C, "<=2025-11-31") -> 0 | F12: =IFERROR(D12/SUMIFS('Cleaned Data'!$H:$H, 'Cleaned Data'!$C:$C, ">=2025-11-01", 'Cleaned Data'!$C:$C, "<=2025-11-31")*100, 0) -> 0 | G12: =IFERROR(B12/E12, 0) -> 0 | H12: =IFERROR(C12/B12, 0) -> 0 | I12: =IFERROR((C12-B12)/B12*100, 0) -> 0
A13: 2025-12 | B13: =SUMIFS('Cleaned Data'!$K:$K, 'Cleaned Data'!$C:$C, ">=2025-12-01", 'Cleaned Data'!$C:$C, "<=2025-12-31") -> 0 | C13: =SUMIFS('Cleaned Data'!$L:$L, 'Cleaned Data'!$C:$C, ">=2025-12-01", 'Cleaned Data'!$C:$C, "<=2025-12-31") -> 0 | D13: =SUMIFS('Cleaned Data'!$J:$J, 'Cleaned Data'!$C:$C, ">=2025-12-01", 'Cleaned Data'!$C:$C, "<=2025-12-31") -> 0 | E13: =SUMIFS('Cleaned Data'!$M:$M, 'Cleaned Data'!$C:$C, ">=2025-12-01", 'Cleaned Data'!$C:$C, "<=2025-12-31") -> 0 | F13: =IFERROR(D13/SUMIFS('Cleaned Data'!$H:$H, 'Cleaned Data'!$C:$C, ">=2025-12-01", 'Cleaned Data'!$C:$C, "<=2025-12-31")*100, 0) -> 0 | G13: =IFERROR(B13/E13, 0) -> 0 | H13: =IFERROR(C13/B13, 0) -> 0 | I13: =IFERROR((C13-B13)/B13*100, 0) -> 0

Sheet Dashboard
A1: MARKETING CAMPAIGN ROI EXECUTIVE DASHBOARD
A3: Interactive Filters: [Marketing Channel] | [Campaign Type] | [Region] | [Date Range]
B5: TOTAL AD SPEND | E5: TOTAL REVENUE | H5: TOTAL CUSTOMERS | K5: TOTAL CONVERSIONS
B6: =SUM('Cleaned Data'!K:K) -> 8202708.7 | E6: =SUM('Cleaned Data'!L:L) -> 1.2993882e+08 | H6: =SUM('Cleaned Data'!M:M) -> 319260 | K6: =SUM('Cleaned Data'!J:J) -> 446338
B8: CONVERSION RATE | E8: CAC | H8: ROAS | K8: PORTFOLIO ROI
B9: =IFERROR(SUM('Cleaned Data'!J:J)/SUM('Cleaned Data'!H:H)*100,0) -> 10.549115 | E9: =IFERROR(SUM('Cleaned Data'!K:K)/SUM('Cleaned Data'!M:M),0) -> 25.69288 | H9: =IFERROR(SUM('Cleaned Data'!L:L)/SUM('Cleaned Data'!K:K),0) -> 15.840965 | K9: =IFERROR((SUM('Cleaned Data'!L:L)-SUM('Cleaned Data'!K:K))/SUM('Cleaned Data'!K:K)*100,0) -> 1484.0965
